<?xml version="1.0"?>
<sdf version="1.6">
  <model name="coro_rocky_sensor_config_2">
    <enable_wind>0</enable_wind>
    <static>0</static>
    <pose>0 0 0.075 0 0 0</pose>
    <link name="base_link">
      <inertial>
        <pose>0 0 0.07 0 0 0</pose>
        <mass>3.176</mass>
        <inertia>
          <ixx>0.0070</ixx>
          <iyy>0.0483</iyy>
          <izz>0.0477</izz>
        </inertia>
      </inertial>

      <collision name="chassis_collision">
        <pose>0 0 0.05 0 0 0</pose>
        <geometry>
          <box>
            <size>0.44 0.11 0.12</size>
          </box>
        </geometry>
      </collision>

      <collision name="tower_collision">
        <pose>0.085 0 0.2 0 0 0</pose>
        <geometry>
          <box>
            <size>0.04 0.24 0.25</size>
          </box>
        </geometry>
      </collision>



      <visual name="chassis_main_visual">
        <pose>0 0 0.03 0 0 0</pose>
        <geometry>
          <box>
            <size>0.44 0.11 0.06</size>
          </box>
        </geometry>
        <material>
          <ambient>0.06 0.06 0.06 1</ambient>
          <diffuse>0.06 0.06 0.06 1</diffuse>
        </material>
      </visual>
      <visual name="chassis_top_visual">
        <pose>0 0 0.08 0 0 0</pose>
        <geometry>
          <box>
            <size>0.22 0.11 0.04</size>
          </box>
        </geometry>
        <material>
          <ambient>0.55 0.95 0.55 1</ambient>
          <diffuse>0.55 0.95 0.55 1</diffuse>
        </material>
      </visual>

      <visual name="sensor_mount_1">
        <pose>0.09 0 0.25 0 0 0</pose>
        <geometry>
          <box>
            <size>0.002 0.13 0.06</size>
          </box>
        </geometry>
        <material>
          <ambient>0.55 0.55 0.55 1</ambient>
          <diffuse>0.55 0.55 0.55 1</diffuse>
        </material>
      </visual>
      <visual name="sensor_mount_2">
        <pose>0.084 -0.076 0.24 0 0 -0.5</pose>
        <geometry>
          <box>
            <size>0.002 0.025 0.04</size>
          </box>
        </geometry>
        <material>
          <ambient>0.55 0.55 0.55 1</ambient>
          <diffuse>0.55 0.55 0.55 1</diffuse>
        </material>
      </visual>
      <visual name="sensor_mount_3">
        <pose>0.084 0.076 0.24 0 0 0.5</pose>
        <geometry>
          <box>
            <size>0.002 0.025 0.04</size>
          </box>
        </geometry>
        <material>
          <ambient>0.55 0.55 0.55 1</ambient>
          <diffuse>0.55 0.55 0.55 1</diffuse>
        </material>
      </visual>
      <visual name="sensor_mount_4">
        <pose>0.085 -0.06 0.18 0 0 0</pose>
        <geometry>
          <box>
            <size>0.01 0.01 0.2</size>
          </box>
        </geometry>
        <material>
          <ambient>0.55 0.55 0.55 1</ambient>
          <diffuse>0.55 0.55 0.55 1</diffuse>
        </material>
      </visual>
      <visual name="sensor_mount_5">
        <pose>0.085 0.06 0.18 0 0 0</pose>
        <geometry>
          <box>
            <size>0.01 0.01 0.2</size>
          </box>
        </geometry>
        <material>
          <ambient>0.55 0.55 0.55 1</ambient>
          <diffuse>0.55 0.55 0.55 1</diffuse>
        </material>
      </visual>

      <visual name="antenna_visual_1">
        <pose>0.098 0.06 0.3 0 0.4 0</pose>
        <geometry>
          <cylinder>
            <length>0.05</length>
            <radius>0.005</radius>
          </cylinder>
        </geometry>
        <material>
          <ambient>0.06 0.06 0.06 1</ambient>
          <diffuse>0.06 0.06 0.06 1</diffuse>
        </material>
      </visual>
      <visual name="antenna_visual_2">
        <pose>0.072 0.06 0.3 0 -0.4 0</pose>
        <geometry>
          <cylinder>
            <length>0.05</length>
            <radius>0.005</radius>
          </cylinder>
        </geometry>
        <material>
          <ambient>0.06 0.06 0.06 1</ambient>
          <diffuse>0.06 0.06 0.06 1</diffuse>
        </material>
      </visual>


      <visual name="axle_visual_front">
        <pose>0.21 0 0 1.5707963267948966 0 0</pose>
        <geometry>
          <cylinder>
            <length>0.21</length>
            <radius>0.01</radius>
          </cylinder>
        </geometry>
        <material>
          <ambient>0.06 0.06 0.06 1</ambient>
          <diffuse>0.06 0.06 0.06 1</diffuse>
        </material>
      </visual>
      <visual name="axle_visual_rear">
        <pose>-0.21 0 0 1.5707963267948966 0 0</pose>
        <geometry>
          <cylinder>
            <length>0.21</length>
            <radius>0.01</radius>
          </cylinder>
        </geometry>
        <material>
          <ambient>0.06 0.06 0.06 1</ambient>
          <diffuse>0.06 0.06 0.06 1</diffuse>
        </material>
      </visual>


      <visual name="d435_realsense_camera_visual">
        <pose>0.09 0 0.26 0 0.46 0</pose>
        <geometry>
          <mesh>
            <scale>0.001 0.001 0.001</scale>
            <uri>meshes/realsense_d435.dae</uri>
          </mesh>
        </geometry>
      </visual>


      <visual name="camera_front_visual">
        <pose>0.095 0.03 0.235 0 0 0</pose>
        <geometry>
          <box>
            <size>0.01 0.03 0.03</size>
          </box>
        </geometry>
        <material>
          <ambient>0.0 0.0 0.0 1.0</ambient>
          <diffuse>0.0 0.0 0.0 1.0</diffuse>
        </material>
      </visual>
      <visual name="camera_lens_front_visual">
        <pose>0.105 0.03 0.235 0 1.5707963267948966 0</pose>
        <geometry>
          <cylinder>
            <length>0.011</length>
            <radius>0.005</radius>
          </cylinder>
        </geometry>
        <material>
          <ambient>0.0 0.0 0.0 1.0</ambient>
          <diffuse>0.0 0.0 0.0 1.0</diffuse>
        </material>
      </visual>

      <visual name="camera_rear_visual">
        <pose>0.085 -0.03 0.235 0 0 0</pose>
        <geometry>
          <box>
            <size>0.01 0.03 0.03</size>
          </box>
        </geometry>
        <material>
          <ambient>0.0 0.0 0.0 1.0</ambient>
          <diffuse>0.0 0.0 0.0 1.0</diffuse>
        </material>
      </visual>
      <visual name="camera_lens_rear_visual">
        <pose>0.075 -0.03 0.235 0 1.5707963267948966 0</pose>
        <geometry>
          <cylinder>
            <length>0.011</length>
            <radius>0.005</radius>
          </cylinder>
        </geometry>
        <material>
          <ambient>0.0 0.0 0.0 1.0</ambient>
          <diffuse>0.0 0.0 0.0 1.0</diffuse>
        </material>
      </visual>
      <visual name="camera_left_visual">
        <pose>0.085 0.07 0.27 0 0 0</pose>
        <geometry>
          <box>
            <size>0.015 0.01 0.015</size>
          </box>
        </geometry>
        <material>
          <ambient>0.0 0.0 0.0 1.0</ambient>
          <diffuse>0.0 0.0 0.0 1.0</diffuse>
        </material>
      </visual>
      <visual name="camera_lens_left_visual">
        <pose>0.085 0.08 0.27 1.5707963267948966 0 0</pose>
        <geometry>
          <cylinder>
            <length>0.011</length>
            <radius>0.005</radius>
          </cylinder>
        </geometry>
        <material>
          <ambient>0.0 0.0 0.0 1.0</ambient>
          <diffuse>0.0 0.0 0.0 1.0</diffuse>
        </material>
      </visual>
      <visual name="camera_right_visual">
        <pose>0.085 -0.07 0.27 0 0 0</pose>
        <geometry>
          <box>
            <size>0.015 0.01 0.015</size>
          </box>
        </geometry>
        <material>
          <ambient>0.0 0.0 0.0 1.0</ambient>
          <diffuse>0.0 0.0 0.0 1.0</diffuse>
        </material>
      </visual>
      <visual name="camera_lens_right_visual">
        <pose>0.085 -0.08 0.27 1.5707963267948966 0 0</pose>
        <geometry>
          <cylinder>
            <length>0.011</length>
            <radius>0.005</radius>
          </cylinder>
        </geometry>
        <material>
          <ambient>0.0 0.0 0.0 1.0</ambient>
          <diffuse>0.0 0.0 0.0 1.0</diffuse>
        </material>
      </visual>

     </link>



     <link name="front_left_wheel_steering_link">
       <pose>0.21 0.11 0 0 0 0</pose>
       <inertial>
         <mass>0.05</mass>
         <inertia>
           <ixx>0.000153</ixx>
           <iyy>0.00025</iyy>
           <izz>0.000153</izz>
         </inertia>
       </inertial>
       <visual name="steering_link_visual">
         <pose>0 0 0 0 0 0</pose>
         <geometry>
           <cylinder>
             <length>0.01</length>
             <radius>0.003</radius>
           </cylinder>
         </geometry>
         <material>
           <ambient>0.04 0.04 0.04 1</ambient>
           <diffuse>0.04 0.04 0.04 1</diffuse>
         </material>
       </visual>
     </link>

     <link name="front_right_wheel_steering_link">
       <pose>0.21 -0.11 0 0 0 0</pose>
       <inertial>
         <mass>0.05</mass>
         <inertia>
           <ixx>0.000153</ixx>
           <iyy>0.00025</iyy>
           <izz>0.000153</izz>
         </inertia>
       </inertial>
       <visual name="steering_link_visual">
         <pose>0 0 0 0 0 0</pose>
         <geometry>
           <cylinder>
             <length>0.01</length>
             <radius>0.003</radius>
           </cylinder>
         </geometry>
         <material>
           <ambient>0.04 0.04 0.04 1</ambient>
           <diffuse>0.04 0.04 0.04 1</diffuse>
         </material>
       </visual>
     </link>

     <link name="front_left_wheel">
       <pose>0.21 0.1425 0 0 0 0</pose>
       <!-- Inertia and size need adjusted -->
       <inertial>
         <mass>0.2</mass>
         <inertia>
           <ixx>0.000358</ixx>
           <iyy>0.0005625</iyy>
           <izz>0.000358</izz>
         </inertia>
       </inertial>
       <collision name="collision">
         <pose>0 0 0 -1.5707963267948966 0 0</pose>
         <geometry>
           <cylinder>
             <length>0.068</length>
             <radius>0.075</radius>
           </cylinder>
         </geometry>
         <surface>
           <friction>
             <ode>
               <mu>1</mu>
               <mu2>1</mu2>
               <fdir1>0 0 1</fdir1>
             </ode>
           </friction>
         </surface>
       </collision>
       <visual name="tire_visual">
         <pose>0 0 0 0 0 0</pose>
         <geometry>
           <mesh>
             <uri>meshes/wheel.dae</uri>
             <scale>0.433 0.618 0.433</scale>
           </mesh>
         </geometry>
       </visual>
       <visual name="axis_visual">
         <pose>0 -0.02 0 1.5707963267948966 0 0</pose>
         <geometry>
           <cylinder>
             <length>0.04</length>
             <radius>0.008</radius>
           </cylinder>
         </geometry>
         <material>
           <ambient>0 0 0 1</ambient>
           <diffuse>0 0 0 1</diffuse>
         </material>
       </visual>
     </link>

     <link name="front_right_wheel">
       <pose>0.21 -0.1425 0 0 0 0</pose>
       <inertial>
         <mass>0.2</mass>
         <inertia>
           <ixx>0.000358</ixx>
           <iyy>0.0005625</iyy>
           <izz>0.000358</izz>
         </inertia>
       </inertial>
       <collision name="collision">
         <pose>0 0 0 1.5707963267948966 0 0</pose>
         <geometry>
           <cylinder>
             <length>0.068</length>
             <radius>0.075</radius>
           </cylinder>
         </geometry>
         <surface>
           <friction>
             <ode>
               <mu>1</mu>
               <mu2>1</mu2>
               <fdir1>0 0 1</fdir1>
             </ode>
           </friction>
         </surface>
       </collision>
       <visual name="tire_visual">
         <pose>0 0 0 0 0 0</pose>
         <geometry>
           <mesh>
             <uri>meshes/wheel.dae</uri>
             <scale>0.433 0.618 0.433</scale>
           </mesh>
         </geometry>
       </visual>
       <visual name="axis_visual">
         <pose>0 0.02 0 1.5707963267948966 0 0</pose>
         <geometry>
           <cylinder>
             <length>0.04</length>
             <radius>0.008</radius>
           </cylinder>
         </geometry>
         <material>
           <ambient>0 0 0 1</ambient>
           <diffuse>0 0 0 1</diffuse>
         </material>
       </visual>
     </link>

     <link name="rear_left_wheel">
       <pose>-0.21 0.1425 0 0 0 0</pose>
       <inertial>
         <mass>0.2</mass>
         <inertia>
           <ixx>0.000358</ixx>
           <iyy>0.0005625</iyy>
           <izz>0.000358</izz>
         </inertia>
       </inertial>
       <collision name="collision">
         <pose>0 0 0 -1.5707963267948966 0 0</pose>
         <geometry>
           <cylinder>
             <length>0.068</length>
             <radius>0.075</radius>
           </cylinder>
         </geometry>
         <surface>
           <friction>
             <ode>
               <mu>1</mu>
               <mu2>1</mu2>
               <fdir1>0 0 1</fdir1>
             </ode>
           </friction>
         </surface>
       </collision>
       <visual name="tire_visual">
         <pose>0 0 0 0 0 0</pose>
         <geometry>
           <mesh>
             <uri>meshes/wheel.dae</uri>
             <scale>0.433 0.618 0.433</scale>
           </mesh>
         </geometry>
       </visual>
       <visual name="axis_visual">
         <pose>0 -0.02 0 1.5707963267948966 0 0</pose>
         <geometry>
           <cylinder>
             <length>0.04</length>
             <radius>0.008</radius>
           </cylinder>
         </geometry>
         <material>
           <ambient>0 0 0 1</ambient>
           <diffuse>0 0 0 1</diffuse>
         </material>
       </visual>
     </link>

     <link name="rear_right_wheel">
       <pose>-0.21 -0.1425 0 0 0 0</pose>
       <inertial>
         <mass>0.2</mass>
         <inertia>
           <ixx>0.000358</ixx>
           <iyy>0.0005625</iyy>
           <izz>0.000358</izz>
         </inertia>
       </inertial>
       <collision name="collision">
         <pose>0 0 0 1.5707963267948966 0 0</pose>
         <geometry>
           <cylinder>
             <length>0.068</length>
             <radius>0.075</radius>
           </cylinder>
         </geometry>
         <surface>
           <friction>
             <ode>
               <mu>1</mu>
               <mu2>1</mu2>
               <fdir1>0 0 1</fdir1>
             </ode>
           </friction>
         </surface>
       </collision>
       <visual name="tire_visual">
         <pose>0 0 0 0 0 0</pose>
         <geometry>
           <mesh>
             <uri>meshes/wheel.dae</uri>
             <scale>0.433 0.618 0.433</scale>
           </mesh>
         </geometry>
       </visual>
       <visual name="axis_visual">
         <pose>0 0.02 0 1.5707963267948966 0 0</pose>
         <geometry>
           <cylinder>
             <length>0.04</length>
             <radius>0.008</radius>
           </cylinder>
         </geometry>
         <material>
           <ambient>0 0 0 1</ambient>
           <diffuse>0 0 0 1</diffuse>
         </material>
       </visual>
     </link>


     <joint name="front_left_wheel_steering_joint" type="revolute">
       <child>front_left_wheel_steering_link</child>
       <parent>base_link</parent>
       <axis>
         <xyz>0 0 1</xyz>
         <limit>
           <lower>-0.6</lower>
           <upper>+0.6</upper>
           <velocity>6.0</velocity>
           <effort>3</effort>
         </limit>
         <use_parent_model_frame>1</use_parent_model_frame>
       </axis>
     </joint>

     <joint name="front_right_wheel_steering_joint" type="revolute">
       <parent>base_link</parent>
       <child>front_right_wheel_steering_link</child>
       <axis>
         <xyz>0 0 1</xyz>
         <limit>
           <lower>-0.6</lower>
           <upper>+0.6</upper>
           <velocity>6.0</velocity>
           <effort>3</effort>
         </limit>
       </axis>
     </joint>


     <joint name="front_left_wheel_joint" type="revolute">
       <child>front_left_wheel</child>
       <parent>front_left_wheel_steering_link</parent>
       <axis>
         <xyz>0 1 0</xyz>
         <limit>
           <lower>-1.79769e+308</lower>
           <upper>+1.79769e+308</upper>
           <velocity>40</velocity>
           <effort>9</effort>
         </limit>
         <use_parent_model_frame>1</use_parent_model_frame>
       </axis>
     </joint>

     <joint name="front_right_wheel_joint" type="revolute">
       <parent>front_right_wheel_steering_link</parent>
       <child>front_right_wheel</child>
       <axis>
         <xyz>0 1 0</xyz>
         <limit>
           <lower>-1.79769e+308</lower>
           <upper>+1.79769e+308</upper>
           <velocity>40</velocity>
           <effort>9</effort>
         </limit>
       </axis>
     </joint>

     <joint name="rear_left_wheel_joint" type="revolute">
       <parent>base_link</parent>
       <child>rear_left_wheel</child>
       <axis>
         <xyz>0 1 0</xyz>
         <limit>
           <lower>-1.79769e+308</lower>
           <upper>+1.79769e+308</upper>
           <velocity>40</velocity>
           <effort>9</effort>
         </limit>
       </axis>
     </joint>

     <joint name="rear_right_wheel_joint" type="revolute">
       <parent>base_link</parent>
       <child>rear_right_wheel</child>
       <axis>
         <xyz>0 1 0</xyz>
         <limit>
           <lower>-1.79769e+308</lower>
           <upper>+1.79769e+308</upper>
           <velocity>40</velocity>
           <effort>9</effort>
         </limit>
       </axis>
     </joint>

   </model>
 </sdf>
